<?xml version="1.0" encoding="utf-8"?>
<!-- =================================================================================== -->
<!-- |    This document was autogenerated by xacro from snake.urdf.xacro               | -->
<!-- |    EDITING THIS FILE BY HAND IS NOT RECOMMENDED                                 | -->
<!-- =================================================================================== -->
<robot name="snake">
  <material name="blue">
    <color rgba="0 0 1 1"/>
  </material>
  <material name="green">
    <color rgba="0 1 0 1"/>
  </material>
  <material name="black">
    <color rgba="0 0 0 1"/>
  </material>
  <material name="white">
    <color rgba="1 1 1 1"/>
  </material>
  <link name="tail">
    <visual>
      <geometry>
        <box size="0.2 0.2 0.2"/>
      </geometry>
      <origin rpy="0 0 0" xyz="0 0 0.15"/>
      <material name="black"/>
    </visual>
    <collision>
      <geometry>
        <box size="0.2 0.2 0.2"/>
      </geometry>
      <origin rpy="0 0 0" xyz="0 0 0.15"/>
    </collision>
    <inertial>
      <mass value="1"/>
      <inertia ixx="1.0" ixy="0.0" ixz="0.0" iyy="1.0" iyz="0.0" izz="1.0"/>
    </inertial>
  </link>
  <joint name="joint_fixed1" type="fixed">
    <parent link="tail"/>
    <child link="joint_cylinder1"/>
    <origin rpy="0 0 0" xyz="0 0.26 0.15"/>
  </joint>
  <link name="joint_cylinder1">
    <visual>
      <geometry>
        <cylinder length="0.4" radius="0.15"/>
      </geometry>
      <origin rpy="0 1.57075 0" xyz="0 0 0"/>
      <material name="blue"/>
    </visual>
    <collision>
      <geometry>
        <cylinder length="0.4" radius="0.15"/>
      </geometry>
      <origin rpy="0 1.57075 0" xyz="0 0 0"/>
    </collision>
    <inertial>
      <mass value="1"/>
      <inertia ixx="1.0" ixy="0.0" ixz="0.0" iyy="1.0" iyz="0.0" izz="1.0"/>
    </inertial>
  </link>
  <joint name="joint1" type="revolute">
    <parent link="joint_cylinder1"/>
    <child link="link1"/>
    <origin rpy="0 0 0" xyz="0 0 0"/>
    <axis xyz="1 0 0"/>
    <dynamics damping="0.0" friction="0.0"/>
    <limit effort="40" lower="-2" upper="2" velocity="2"/>
  </joint>
  <link name="link1">
    <visual>
      <geometry>
        <box size="0.2 0.5 0.2"/>
      </geometry>
      <origin rpy="0 0 0" xyz="0 0.41 0"/>
      <material name="white"/>
    </visual>
    <collision>
      <geometry>
        <box size="0.2 0.5 0.2"/>
      </geometry>
      <origin rpy="0 0 0" xyz="0 0.41 0"/>
    </collision>
    <inertial>
      <mass value="1"/>
      <inertia ixx="1.0" ixy="0.0" ixz="0.0" iyy="1.0" iyz="0.0" izz="1.0"/>
    </inertial>
  </link>
  <!-- This block provides the simulator (Gazebo) with information on a few additional
        physical properties. See http://gazebosim.org/tutorials/?tut=ros_urdf for more-->
  <gazebo reference="link1">
    <mu1 value="200.0"/>
    <mu2 value="100.0"/>
    <kp value="10000000.0"/>
    <kd value="1.0"/>
    <material>Gazebo/Grey</material>
  </gazebo>
  <!-- This block connects the wheel joint to an actuator (motor), which informs both
        simulation and visualization of the robot -->
  <transmission name="joint1_trans">
    <type>transmission_interface/SimpleTransmission</type>
    <actuator name="joint1_motor">
      <hardwareInterface>hardware_interface/EffortJointInterface</hardwareInterface>
      <mechanicalReduction>1</mechanicalReduction>
    </actuator>
    <joint name="joint1">
      <hardwareInterface>hardware_interface/EffortJointInterface</hardwareInterface>
    </joint>
  </transmission>
  <joint name="joint_fixed2" type="fixed">
    <parent link="link1"/>
    <child link="joint_cylinder2"/>
    <origin rpy="0 0 0" xyz="0 0.82 0"/>
  </joint>
  <link name="joint_cylinder2">
    <visual>
      <geometry>
        <cylinder length="0.4" radius="0.15"/>
      </geometry>
      <origin rpy="0 1.57075 0" xyz="0 0 0"/>
      <material name="blue"/>
    </visual>
    <collision>
      <geometry>
        <cylinder length="0.4" radius="0.15"/>
      </geometry>
      <origin rpy="0 1.57075 0" xyz="0 0 0"/>
    </collision>
    <inertial>
      <mass value="1"/>
      <inertia ixx="1.0" ixy="0.0" ixz="0.0" iyy="1.0" iyz="0.0" izz="1.0"/>
    </inertial>
  </link>
  <joint name="joint2" type="revolute">
    <parent link="joint_cylinder2"/>
    <child link="link2"/>
    <origin rpy="0 0 0" xyz="0 0 0"/>
    <axis xyz="1 0 0"/>
    <dynamics damping="0.0" friction="0.0"/>
    <limit effort="40" lower="-2" upper="2" velocity="2"/>
  </joint>
  <link name="link2">
    <visual>
      <geometry>
        <box size="0.2 0.5 0.2"/>
      </geometry>
      <origin rpy="0 0 0" xyz="0 0.41 0"/>
      <material name="white"/>
    </visual>
    <collision>
      <geometry>
        <box size="0.2 0.5 0.2"/>
      </geometry>
      <origin rpy="0 0 0" xyz="0 0.41 0"/>
    </collision>
    <inertial>
      <mass value="1"/>
      <inertia ixx="1.0" ixy="0.0" ixz="0.0" iyy="1.0" iyz="0.0" izz="1.0"/>
    </inertial>
  </link>
  <!-- This block provides the simulator (Gazebo) with information on a few additional
        physical properties. See http://gazebosim.org/tutorials/?tut=ros_urdf for more-->
  <gazebo reference="link2">
    <mu1 value="200.0"/>
    <mu2 value="100.0"/>
    <kp value="10000000.0"/>
    <kd value="1.0"/>
    <material>Gazebo/Grey</material>
  </gazebo>
  <!-- This block connects the wheel joint to an actuator (motor), which informs both
        simulation and visualization of the robot -->
  <transmission name="joint2_trans">
    <type>transmission_interface/SimpleTransmission</type>
    <actuator name="joint2_motor">
      <hardwareInterface>hardware_interface/EffortJointInterface</hardwareInterface>
      <mechanicalReduction>1</mechanicalReduction>
    </actuator>
    <joint name="joint2">
      <hardwareInterface>hardware_interface/EffortJointInterface</hardwareInterface>
    </joint>
  </transmission>
  <joint name="joint_fixed3" type="fixed">
    <parent link="link2"/>
    <child link="joint_cylinder3"/>
    <origin rpy="0 0 0" xyz="0 0.82 0"/>
  </joint>
  <link name="joint_cylinder3">
    <visual>
      <geometry>
        <cylinder length="0.4" radius="0.15"/>
      </geometry>
      <origin rpy="0 1.57075 0" xyz="0 0 0"/>
      <material name="blue"/>
    </visual>
    <collision>
      <geometry>
        <cylinder length="0.4" radius="0.15"/>
      </geometry>
      <origin rpy="0 1.57075 0" xyz="0 0 0"/>
    </collision>
    <inertial>
      <mass value="1"/>
      <inertia ixx="1.0" ixy="0.0" ixz="0.0" iyy="1.0" iyz="0.0" izz="1.0"/>
    </inertial>
  </link>
  <joint name="joint3" type="revolute">
    <parent link="joint_cylinder3"/>
    <child link="link3"/>
    <origin rpy="0 0 0" xyz="0 0 0"/>
    <axis xyz="1 0 0"/>
    <dynamics damping="0.0" friction="0.0"/>
    <limit effort="40" lower="-2" upper="2" velocity="2"/>
  </joint>
  <link name="link3">
    <visual>
      <geometry>
        <box size="0.2 0.5 0.2"/>
      </geometry>
      <origin rpy="0 0 0" xyz="0 0.41 0"/>
      <material name="white"/>
    </visual>
    <collision>
      <geometry>
        <box size="0.2 0.5 0.2"/>
      </geometry>
      <origin rpy="0 0 0" xyz="0 0.41 0"/>
    </collision>
    <inertial>
      <mass value="1"/>
      <inertia ixx="1.0" ixy="0.0" ixz="0.0" iyy="1.0" iyz="0.0" izz="1.0"/>
    </inertial>
  </link>
  <!-- This block provides the simulator (Gazebo) with information on a few additional
        physical properties. See http://gazebosim.org/tutorials/?tut=ros_urdf for more-->
  <gazebo reference="link3">
    <mu1 value="200.0"/>
    <mu2 value="100.0"/>
    <kp value="10000000.0"/>
    <kd value="1.0"/>
    <material>Gazebo/Grey</material>
  </gazebo>
  <!-- This block connects the wheel joint to an actuator (motor), which informs both
        simulation and visualization of the robot -->
  <transmission name="joint3_trans">
    <type>transmission_interface/SimpleTransmission</type>
    <actuator name="joint3_motor">
      <hardwareInterface>hardware_interface/EffortJointInterface</hardwareInterface>
      <mechanicalReduction>1</mechanicalReduction>
    </actuator>
    <joint name="joint3">
      <hardwareInterface>hardware_interface/EffortJointInterface</hardwareInterface>
    </joint>
  </transmission>
  <joint name="joint_fixed4" type="fixed">
    <parent link="link3"/>
    <child link="joint_cylinder4"/>
    <origin rpy="0 0 0" xyz="0 0.82 0"/>
  </joint>
  <link name="joint_cylinder4">
    <visual>
      <geometry>
        <cylinder length="0.4" radius="0.15"/>
      </geometry>
      <origin rpy="0 1.57075 0" xyz="0 0 0"/>
      <material name="blue"/>
    </visual>
    <collision>
      <geometry>
        <cylinder length="0.4" radius="0.15"/>
      </geometry>
      <origin rpy="0 1.57075 0" xyz="0 0 0"/>
    </collision>
    <inertial>
      <mass value="1"/>
      <inertia ixx="1.0" ixy="0.0" ixz="0.0" iyy="1.0" iyz="0.0" izz="1.0"/>
    </inertial>
  </link>
  <joint name="joint4" type="revolute">
    <parent link="joint_cylinder4"/>
    <child link="link4"/>
    <origin rpy="0 0 0" xyz="0 0 0"/>
    <axis xyz="1 0 0"/>
    <dynamics damping="0.0" friction="0.0"/>
    <limit effort="40" lower="-2" upper="2" velocity="2"/>
  </joint>
  <link name="link4">
    <visual>
      <geometry>
        <box size="0.2 0.5 0.2"/>
      </geometry>
      <origin rpy="0 0 0" xyz="0 0.41 0"/>
      <material name="white"/>
    </visual>
    <collision>
      <geometry>
        <box size="0.2 0.5 0.2"/>
      </geometry>
      <origin rpy="0 0 0" xyz="0 0.41 0"/>
    </collision>
    <inertial>
      <mass value="1"/>
      <inertia ixx="1.0" ixy="0.0" ixz="0.0" iyy="1.0" iyz="0.0" izz="1.0"/>
    </inertial>
  </link>
  <!-- This block provides the simulator (Gazebo) with information on a few additional
        physical properties. See http://gazebosim.org/tutorials/?tut=ros_urdf for more-->
  <gazebo reference="link4">
    <mu1 value="200.0"/>
    <mu2 value="100.0"/>
    <kp value="10000000.0"/>
    <kd value="1.0"/>
    <material>Gazebo/Grey</material>
  </gazebo>
  <!-- This block connects the wheel joint to an actuator (motor), which informs both
        simulation and visualization of the robot -->
  <transmission name="joint4_trans">
    <type>transmission_interface/SimpleTransmission</type>
    <actuator name="joint4_motor">
      <hardwareInterface>hardware_interface/EffortJointInterface</hardwareInterface>
      <mechanicalReduction>1</mechanicalReduction>
    </actuator>
    <joint name="joint4">
      <hardwareInterface>hardware_interface/EffortJointInterface</hardwareInterface>
    </joint>
  </transmission>
  <joint name="joint_fixed5" type="fixed">
    <parent link="link4"/>
    <child link="joint_cylinder5"/>
    <origin rpy="0 0 0" xyz="0 0.82 0"/>
  </joint>
  <link name="joint_cylinder5">
    <visual>
      <geometry>
        <cylinder length="0.4" radius="0.15"/>
      </geometry>
      <origin rpy="0 1.57075 0" xyz="0 0 0"/>
      <material name="blue"/>
    </visual>
    <collision>
      <geometry>
        <cylinder length="0.4" radius="0.15"/>
      </geometry>
      <origin rpy="0 1.57075 0" xyz="0 0 0"/>
    </collision>
    <inertial>
      <mass value="1"/>
      <inertia ixx="1.0" ixy="0.0" ixz="0.0" iyy="1.0" iyz="0.0" izz="1.0"/>
    </inertial>
  </link>
  <joint name="joint5" type="revolute">
    <parent link="joint_cylinder5"/>
    <child link="link5"/>
    <origin rpy="0 0 0" xyz="0 0 0"/>
    <axis xyz="1 0 0"/>
    <dynamics damping="0.0" friction="0.0"/>
    <limit effort="40" lower="-2" upper="2" velocity="2"/>
  </joint>
  <link name="link5">
    <visual>
      <geometry>
        <box size="0.2 0.5 0.2"/>
      </geometry>
      <origin rpy="0 0 0" xyz="0 0.41 0"/>
      <material name="white"/>
    </visual>
    <collision>
      <geometry>
        <box size="0.2 0.5 0.2"/>
      </geometry>
      <origin rpy="0 0 0" xyz="0 0.41 0"/>
    </collision>
    <inertial>
      <mass value="1"/>
      <inertia ixx="1.0" ixy="0.0" ixz="0.0" iyy="1.0" iyz="0.0" izz="1.0"/>
    </inertial>
  </link>
  <!-- This block provides the simulator (Gazebo) with information on a few additional
        physical properties. See http://gazebosim.org/tutorials/?tut=ros_urdf for more-->
  <gazebo reference="link5">
    <mu1 value="200.0"/>
    <mu2 value="100.0"/>
    <kp value="10000000.0"/>
    <kd value="1.0"/>
    <material>Gazebo/Grey</material>
  </gazebo>
  <!-- This block connects the wheel joint to an actuator (motor), which informs both
        simulation and visualization of the robot -->
  <transmission name="joint5_trans">
    <type>transmission_interface/SimpleTransmission</type>
    <actuator name="joint5_motor">
      <hardwareInterface>hardware_interface/EffortJointInterface</hardwareInterface>
      <mechanicalReduction>1</mechanicalReduction>
    </actuator>
    <joint name="joint5">
      <hardwareInterface>hardware_interface/EffortJointInterface</hardwareInterface>
    </joint>
  </transmission>
  <joint name="joint_fixed_start" type="fixed">
    <parent link="link5"/>
    <child link="head"/>
    <origin rpy="0 0 0" xyz="0 0.9 0 "/>
  </joint>
  <link name="head">
    <visual>
      <geometry>
        <sphere radius="0.2"/>
      </geometry>
      <origin rpy="0 0 0" xyz="0 0 0"/>
      <material name="green"/>
    </visual>
    <collision>
      <geometry>
        <sphere radius="0.2"/>
      </geometry>
      <origin rpy="0 0 0" xyz="0 0 0"/>
    </collision>
    <inertial>
      <mass value="1"/>
      <inertia ixx="1.0" ixy="0.0" ixz="0.0" iyy="1.0" iyz="0.0" izz="1.0"/>
    </inertial>
  </link>
  <!-- Gazebo plugin for ROS Control -->
  <gazebo>
    <plugin filename="libgazebo_ros_control.so" name="gazebo_ros_control">
      <robotNamespace>/snake</robotNamespace>
    </plugin>
  </gazebo>
</robot>
